<robot name="pi_robot">

    <link name="base_link">
        <visual>
            <origin xyz="0 0 0.5" rpy="0 0 0"/>
            <geometry>
                <box size="5.0 5.0 0.085"/>
            </geometry>
            <material name="Cyan1">
                <color rgba="0.2 0.3 0.9 1.0"/>
            </material>
        </visual>
    </link>

    <link name="torso_link">
        <visual>
            <origin xyz="0 0 0.57" rpy="0 0 0"/>
            <geometry>
                <cylinder radius="1.5" length="2"/>
            </geometry>
            <material name="Yellow2">
                <color rgba="0.8 0.8 0 1.0"/>
            </material>
        </visual>
    </link>

    <link name="shoulder_link">
        <visual>
            <origin xyz="0 0 1.5" rpy="0 0 0"/>
            <geometry>
                <box size="1.5 1.5 3"/>
            </geometry>
            <material name="Red">
                <color rgba="1 0 0 1.0"/>
            </material>
        </visual>
    </link>

    <link name="upper_arm_link">
        <visual>
            <origin xyz="0 0 2.0" rpy="0 0 0"/>
            <geometry>
                <cylinder radius="1.0" length="3.0"/>
            </geometry>
            <material name="Green">
                <color rgba="0 1 0 1.0"/>
            </material>
        </visual>
    </link>

    <link name="forearm_link">
        <visual>
            <origin xyz="0 0 3.0" rpy="0 0 0"/>
            <geometry>
                <cylinder radius="1.0" length="5"/>
            </geometry>
            <material name="Blue">
                <color rgba="0 0 1 1.0"/>
            </material>
        </visual>
    </link>

    <link name="wrist_link">
        <visual>
            <origin xyz="0 0 3.6" rpy="0 0 0"/>
            <geometry>
                <box size="1.3 1.3 4"/>
            </geometry>
            <material name="Yellow">
                <color rgba="1 1 0 1.0"/>
            </material>
        </visual>
    </link>

    <link name="end_effector_link">
        <visual>
            <origin xyz="0 0 3.7" rpy="0 0 0"/>
            <geometry>
                <box size="1.0 1.0 4"/>
            </geometry>
            <material name="Magenta">
                <color rgba="1 0 1 1.0"/>
            </material>
        </visual>
    </link>

    <!-- Joint Definitions -->

    <joint name="torso_joint" type="revolute">
        <parent link="base_link"/>
        <child link="torso_link"/>
        <origin xyz="0 0 1.07" rpy="0 0 0"/>
        <axis xyz="0 0 1"/>
        <limit lower="-3.14" upper="3.14" effort="10" velocity="3"/>
    </joint>

    <joint name="shoulder_pitch_joint" type="revolute">
        <parent link="torso_link"/>
        <child link="shoulder_link"/>
        <origin xyz="0 0 2.0" rpy="0 0 0"/>
        <axis xyz="0 1 0"/>
        <limit lower="-1.57" upper="1.57" effort="10" velocity="3"/>
    </joint>

    <joint name="shoulder_roll_joint" type="revolute">
        <parent link="shoulder_link"/>
        <child link="upper_arm_link"/>
        <origin xyz="0 0 3.0" rpy="0 0 0"/>
        <axis xyz="1 0 0"/>
        <limit lower="-1.57" upper="1.57" effort="10" velocity="3"/>
    </joint>

    <joint name="elbow_pitch_joint" type="revolute">
        <parent link="upper_arm_link"/>
        <child link="forearm_link"/>
        <origin xyz="0 0 4.0" rpy="0 0 0"/>
        <axis xyz="0 1 0"/>
        <limit lower="-1.57" upper="1.57" effort="10" velocity="3"/>
    </joint>

    <joint name="wrist_roll_joint" type="revolute">
        <parent link="forearm_link"/>
        <child link="wrist_link"/>
        <origin xyz="0 0 4.6" rpy="0 0 0"/>
        <axis xyz="1 0 0"/>
        <limit lower="-2.1" upper="2.1" effort="10" velocity="3"/>
    </joint>

    <joint name="wrist_pitch_joint" type="revolute">
        <parent link="wrist_link"/>
        <child link="end_effector_link"/>
        <origin xyz="0 0 4.8" rpy="0 0 0"/>
        <axis xyz="0 1 0"/>
        <limit lower="-2.1" upper="2.1" effort="10" velocity="3"/>
    </joint>

</robot>

